Workbook

Sheet 前提・予算
A1: B社 販売・在庫管理システム AWSモダナイズPJ ― 前提条件と予算配分
A3: 入力項目 | B3: 値 | C3: 根拠・備考
A4: 予算総額（万円） | B4: 10000 | C4: 課題条件
A5: 社員単価（万円/人月） | B5: 150 | C5: 課題条件
A6: パートナー単価（万円/人月） | B6: 100 | C6: 課題条件
A7: パートナー比率上限 | B7: 0.6 | C7: 課題条件（人数・人月・各月の要員数のいずれでも満たす）
A8: AWS利用料・ツール費（万円） | B8: 500 | C8: 開発/検証/本番環境12ヶ月分＋開発ツール。想定値
A10: 予算配分・チェック | B10: 値 | C10: 備考
A11: 人件費（社員） | B11: =要員計画!B35 -> 5625 | C11: 要員計画シートより
A12: 人件費（パートナー） | B12: =要員計画!C35 -> 3200 | C12: 要員計画シートより
A13: AWS利用料・ツール費 | B13: =B8 -> 500
A14: 予備費（リスク対応） | B14: =B4-SUM(B11:B13) -> 675 | C14: スコープ変更・遅延対応に充当。ステコミ承認で執行
A15: 合計（万円） | B15: =SUM(B11:B14) -> 10000 | C15: 予算総額と一致
A16: 予備費率 | B16: =B14/B4 -> 0.0675 | C16: 目安5〜10%
A17: 総工数（人月） | B17: =要員計画!D34 -> 69.5 | C17: 当社（社員＋パートナー）
A18: パートナー比率（人数） | B18: =要員計画!E33 -> 0.6 | C18: 社員4名・パートナー6名
A19: パートナー比率（人月） | B19: =要員計画!E34 -> 0.46043165
A20: パートナー比率（月別の最大） | B20: =要員計画!E36 -> 0.6 | C20: ピーク月（M7〜M8）
A21: 上限60%チェック | B21: =要員計画!E37 -> OK | C21: 3指標すべてで上限以内
A23: プロジェクト前提・方針
A24: 【進め方】全面再構築ではなく「段階的モダナイズ」。本PJ（フェーズ1）は販売・在庫のコア業務をAWS上の新アーキテクチャへ移行し、周辺機能・帳票の高度化はフェーズ2とする。
A25: 【理由】1億円・12ヶ月（約70人月）で基幹全体の作り直しは非現実的。コア機能に絞り、業務停止リスクを抑えて確実にリリースする。
A26: 【スケジュール】M1〜M12。本番リリースはM11末、M12はハイパーケア・運用引継ぎ・旧環境停止（移行完了）。
A27: 【切替時期】B社の月末締め・決算期を避けて切替日を設定する（要件定義で確定）。
A28: 【窓口】B社との窓口は情シスPJ推進担当に一本化。既存ベンダーへの照会も情シス経由（または三者連絡会）で行う。
A29: 【予算外】B社側作業（【顧客】タスク）と既存ベンダーの作業（B社との保守契約で対応）は本予算外。当社事業部長はPJ工数外。
A30: 【体制】PM・業務リード・アーキテクト・開発リーダーの要所4名を社員で固め、パートナーは実装・基盤構築・テスト・移行に配置。

Sheet WBS
A1: ① WBS（作業分解構成図）
B2: ◆＝マイルストーン（フェーズゲート：ステコミで判定） 【顧客】＝B社側タスク 【既存ベンダー】＝既存ベンダー側タスク | H2: ■ | I2: フェーズ | K2: ■ | L2: 当社 | N2: ■ | O2: 顧客 | Q2: ■ | R2: 既存ﾍﾞﾝﾀﾞｰ
A4: WBS No | B4: 作業項目 | C4: 成果物 | D4: 担当 | E4: 開始月 | F4: 終了月 | G4: 工数 (人月) | H4: M1 | I4: M2 | J4: M3 | K4: M4 | L4: M5 | M4: M6 | N4: M7 | O4: M8 | P4: M9 | Q4: M10 | R4: M11 | S4: M12
B5: 主要マイルストーン | H5: ◆ | J5: ◆ | L5: ◆ | O5: ◆ | Q5: ◆ | R5: ◆ | S5: ◆
A6: 1 | B6: プロジェクト管理 | E6: 1 | F6: 12 | G6: =SUM(G7:G13) -> 10 | H6: ■ | I6: ■ | J6: ■ | K6: ■ | L6: ■ | M6: ■ | N6: ■ | O6: ■ | P6: ■ | Q6: ■ | R6: ■ | S6: ■
A7: 1.1 | B7: プロジェクト計画書作成 | C7: プロジェクト計画書 | D7: PMチーム | E7: 1 | F7: 1 | G7: 1 | H7: ■
A8: 1.2 | B8: 【顧客】プロジェクト計画・予算の承認 | C8: 承認記録 | D8: B社 PO（管掌役員） | E8: 1 | F8: 1 | G8: ― | H8: ■
A9: 1.3 | B9: 進捗・課題・リスク管理（週次定例運営） | C9: 週次報告書・課題/リスク管理表 | D9: PMチーム | E9: 1 | F9: 12 | G9: 4.5 | H9: ■ | I9: ■ | J9: ■ | K9: ■ | L9: ■ | M9: ■ | N9: ■ | O9: ■ | P9: ■ | Q9: ■ | R9: ■ | S9: ■
A10: 1.4 | B10: ステアリングコミッティ運営・フェーズゲート判定準備 | C10: ステコミ資料・議事録 | D10: PMチーム | E10: 1 | F10: 12 | G10: 1.5 | H10: ■ | I10: ■ | J10: ■ | K10: ■ | L10: ■ | M10: ■ | N10: ■ | O10: ■ | P10: ■ | Q10: ■ | R10: ■ | S10: ■
A11: 1.5 | B11: 変更管理・予算（予実）管理 | C11: 変更管理票・予実管理表 | D11: PMチーム | E11: 1 | F11: 12 | G11: 1.5 | H11: ■ | I11: ■ | J11: ■ | K11: ■ | L11: ■ | M11: ■ | N11: ■ | O11: ■ | P11: ■ | Q11: ■ | R11: ■ | S11: ■
A12: 1.6 | B12: 品質管理（レビュー計画・品質指標のモニタリング） | C12: 品質計画書・品質報告 | D12: PMチーム | E12: 1 | F12: 12 | G12: 1 | H12: ■ | I12: ■ | J12: ■ | K12: ■ | L12: ■ | M12: ■ | N12: ■ | O12: ■ | P12: ■ | Q12: ■ | R12: ■ | S12: ■
A13: 1.7 | B13: プロジェクト完了報告・振り返り | C13: 完了報告書・教訓録 | D13: PMチーム | E13: 12 | F13: 12 | G13: 0.5 | S13: ■
A14: 2 | B14: 立上げ | E14: 1 | F14: 1 | G14: =SUM(G15:G20) -> 1.5 | H14: ■
A15: 2.1 | B15: キックオフ準備・開催（B社・既存ベンダー含む） | C15: キックオフ資料 | D15: PMチーム | E15: 1 | F15: 1 | G15: 0.5 | H15: ■
A16: 2.2 | B16: ステークホルダー分析・コミュニケーション計画策定 | C16: 体制図・会議体定義書 | D16: PMチーム | E16: 1 | F16: 1 | G16: 0.5 | H16: ■
A17: 2.3 | B17: 【顧客】キーパーソン（KP）の任命・要件定義権限の付与 | C17: 任命通知 | D17: B社 ユーザー部門長 | E17: 1 | F17: 1 | G17: ― | H17: ■
A18: 2.4 | B18: 【顧客】既存ベンダーへの協力依頼・協力範囲の契約調整 | C18: 協力依頼書・契約変更 | D18: B社 情シスPJ推進 | E18: 1 | F18: 1 | G18: ― | H18: ■
A19: 2.5 | B19: 開発標準・プロジェクト管理ツール整備 | C19: 開発標準書 | D19: 基盤チーム | E19: 1 | F19: 1 | G19: 0.5 | H19: ■
B20: ◆ キックオフ | D20: ステアリングコミッティ | E20: 1 | F20: 1 | H20: ◆
A21: 3 | B21: 現行調査・要件定義 | E21: 1 | F21: 4 | G21: =SUM(G22:G32) -> 7.5 | H21: ■ | I21: ■ | J21: ■ | K21: ■
A22: 3.1 | B22: 現行システム資産調査（機能・データ・IF） | C22: 現行資産一覧・現行仕様整理 | D22: 基盤チーム | E22: 1 | F22: 2 | G22: 1.5 | H22: ■ | I22: ■
A23: 3.2 | B23: 【既存ベンダー】現行仕様書・資料の提供、仕様照会への回答 | C23: 現行仕様書・照会回答 | D23: 既存ベンダー窓口 | E23: 1 | F23: 4 | G23: ― | H23: ■ | I23: ■ | J23: ■ | K23: ■
A24: 3.3 | B24: As-Is業務ヒアリング（営業・経理） | C24: 業務フロー（As-Is）・課題一覧 | D24: 業務チーム | E24: 1 | F24: 2 | G24: 1.5 | H24: ■ | I24: ■
A25: 3.4 | B25: 【顧客】現行業務・課題の説明 | C25: ― | D25: B社 KP（営業・経理） | E25: 1 | F25: 2 | G25: ― | H25: ■ | I25: ■
A26: 3.5 | B26: To-Be業務・機能要件定義 | C26: 要件定義書（機能） | D26: 業務チーム | E26: 2 | F26: 3 | G26: 2.5 | I26: ■ | J26: ■
A27: 3.6 | B27: 【顧客】業務要件の決定（部門内合意） | C27: 要件決定記録 | D27: B社 KP（営業・経理） | E27: 2 | F27: 3 | G27: ― | I27: ■ | J27: ■
A28: 3.7 | B28: 非機能要件定義（性能・可用性・セキュリティ） | C28: 要件定義書（非機能） | D28: 基盤チーム | E28: 2 | F28: 3 | G28: 1 | I28: ■ | J28: ■
A29: 3.8 | B29: 移行方針策定（移行対象・範囲・方式） | C29: 移行方針書 | D29: 業務チーム | E29: 3 | F29: 3 | G29: 0.5 | J29: ■
A30: 3.9 | B30: スコープ確定（フェーズ1/2の切り分け） | C30: スコープ定義書 | D30: PMチーム | E30: 3 | F30: 3 | G30: 0.5 | J30: ■
A31: 3.10 | B31: 【顧客】要件定義書の承認・スコープの最終決裁 | C31: 承認記録 | D31: B社 PO（管掌役員） | E31: 3 | F31: 3 | G31: ― | J31: ■
B32: ◆ G1 要件定義完了・スコープ合意 | D32: ステアリングコミッティ | E32: 3 | F32: 3 | J32: ◆
A33: 4 | B33: アーキテクチャ設計・AWS基盤構築 | E33: 2 | F33: 6 | G33: =SUM(G34:G39) -> 6 | I33: ■ | J33: ■ | K33: ■ | L33: ■ | M33: ■
A34: 4.1 | B34: AWSアーキテクチャ設計（コンテナ・マネージドDB等） | C34: アーキテクチャ設計書 | D34: 基盤チーム | E34: 2 | F34: 3 | G34: 1.5 | I34: ■ | J34: ■
A35: 4.2 | B35: セキュリティ・ネットワーク設計 | C35: セキュリティ設計書 | D35: 基盤チーム | E35: 3 | F35: 3 | G35: 0.5 | J35: ■
A36: 4.3 | B36: 【顧客】セキュリティ設計の承認（社内規程適合確認） | C36: 承認記録 | D36: B社 情シスPJ推進 | E36: 3 | F36: 3 | G36: ― | J36: ■
A37: 4.4 | B37: 技術検証（PoC：性能・IF疎通） | C37: PoC報告書 | D37: 基盤チーム | E37: 3 | F37: 4 | G37: 1 | J37: ■ | K37: ■
A38: 4.5 | B38: 環境構築（開発/検証/本番・IaC） | C38: 構築手順書・IaCコード | D38: 基盤チーム | E38: 4 | F38: 5 | G38: 1.5 | K38: ■ | L38: ■
A39: 4.6 | B39: CI/CD・監視基盤構築 | C39: CI/CDパイプライン・監視設定 | D39: 基盤チーム | E39: 5 | F39: 6 | G39: 1.5 | L39: ■ | M39: ■
A40: 5 | B40: 設計 | E40: 4 | F40: 5 | G40: =SUM(G41:G46) -> 8.5 | K40: ■ | L40: ■
A41: 5.1 | B41: 基本設計（画面・帳票・バッチ） | C41: 基本設計書 | D41: 業務チーム | E41: 4 | F41: 5 | G41: 2.5 | K41: ■ | L41: ■
...

Sheet 体制図
B1: ② プロジェクト体制図
B3: B社（発注者） | H3: 当社（受注者） | X3: 既存ベンダー
B5: ステアリングコミッティ（月次＋フェーズゲート時） B社：PO（管掌役員）・ユーザー部門長（営業・経理）・情シスPJ推進 ／ 当社：事業部長・PM
B7: ↓ 報告・エスカレーション ↑ 意思決定
B8: プロジェクトオーナー （管掌役員） 予算・スコープの最終決裁 【B社 PO】 | H8: 当社 事業部長（当社責任者） 要員確保・当社内エスカレーション先 ※PJ工数外 | X8: 既存ベンダー （B社と現行保守契約）
E11: ↓ | O11: ↓ | Z11: ↓
B12: 情シス部門 PJ推進担当（2名） 窓口一本化・社内調整 運用引継ぎの受け手 【B社 情シスPJ推進】 | G12: ⇔ 窓口 一本化 | H12: プロジェクトマネージャー（社員）1名 【PMチーム】 計画・進捗・課題・リスク・予算・変更管理／品質管理 B社窓口（情シスPJ推進）との唯一の公式窓口 | W12: ⇔ 照会 (情シス 経由) | X12: 既存ベンダー窓口 引継ぎ協力・ 現行仕様照会の窓口 【既存ベンダー窓口】
O16: ↓
B17: ユーザー部門長 （営業部長・経理部長） KPを任命・受入判定 【B社 ユーザー部門長】 | H17: 【業務チーム】 業務リード （社員）1名 業務SE （P）1名 ― 要件定義・基本設計 UAT支援・教育 | K17: 【基盤チーム】 アーキテクト （社員）1名 AWSエンジニア （P）1名 ― AWS設計・構築 IF設計・運用引継ぎ | N17: 【開発チーム】 開発リーダー （社員）1名 開発メンバー （P）2名 ― 詳細設計・開発 不具合修正 | Q17: 【テストチーム】 テスト担当 （P）1名 ― テスト計画・実施 品質評価 | T17: 【移行チーム】 移行担当 （P）1名 ― 移行設計・ツール リハーサル・本番 | X17: 主な協力事項 ・現行仕様書の提供 ・仕様照会への回答 ・現行データの抽出 ・切替時の旧環境運用 ・旧環境停止・保守終了
B20: ↓ 任命
B21: ユーザー部門キーパーソン 営業 1〜2名・経理 1〜2名 要件定義権限を持つ担当 要件決定・UAT・社内展開 【B社 KP（営業・経理）】
B27: ="当社要員：社員 "&要員計画!B33&"名／パートナー "&要員計画!C33&"名 パートナー比率：人数 "&TEXT(要員計画!E33,"0%")&"・人月 "&TEXT(要員計画!E34,"0.0%")&"・月別最大 "&TEXT(要員計画!E36,"0%")&"（上限60%）" -> 当社要員：社員 4名／パートナー 6名 パートナー比率：人数 60%・人月 46.0%・月別最大 60%（上限60%）
B28: 凡例：（P）＝パートナー要員 ／ 【 】内はWBS担当欄の名称 ／ 橙＝B社・青＝当社・緑＝既存ベンダー ／ 既存ベンダーはB社と契約（当社は直接契約しない）
B30: 会議体
B31: 名称 | G31: 目的 | Q31: 頻度 | V31: 参加者
B32: ステアリングコミッティ | G32: 進捗・予算・リスクの報告、フェーズゲート（G1〜G6）判定、スコープ変更・予備費執行の決裁 | Q32: 月次＋フェーズゲート時 | V32: B社 PO（議長）・ユーザー部門長・情シスPJ推進／当社 事業部長・PM
B33: 定例進捗会議 | G33: 進捗・課題・リスクの共有と対応決定、B社への依頼事項・期限の確認 | Q33: 週次 | V33: B社 情シスPJ推進／当社 PM・各チームリーダー（KPは議題に応じて）
B34: 要件・仕様確認会 | G34: 業務要件の決定、画面・帳票イメージの確認、UAT計画・結果の確認（KPの決定事項を記録） | Q34: 要件定義期：週2回 設計期：週次／以降：隔週 | V34: B社 KP（営業・経理）・情シスPJ推進／当社 業務チーム・PM
B35: 技術レビュー会 | G35: アーキテクチャ・セキュリティ・運用設計のレビュー、情シス規程への適合確認 | Q35: 設計期：隔週 以降：随時 | V35: B社 情シスPJ推進／当社 基盤チーム（アーキテクト）・開発リーダー
B36: 三者連絡会 | G36: 現行仕様照会の回答管理、データ抽出・切替・旧環境停止の調整（依頼は情シス経由で一本化） | Q36: 隔週 （移行期M9〜M12は週次） | V36: B社 情シスPJ推進／既存ベンダー窓口／当社 PM・基盤チーム・移行チーム
B37: 移行判定会（Go/No-Go） | G37: 移行リハーサル結果・品質評価に基づく本番移行可否の判定、切り戻し条件の確認 | Q37: リハーサル②後・本番前（M10〜M11） | V37: B社 PO・ユーザー部門長・情シスPJ推進／既存ベンダー窓口／当社 PM・全チームリーダー
B38: 社内プロジェクトレビュー | G38: 当社品質保証部門による第三者チェック（計画妥当性・品質・予算） | Q38: 月次＋フェーズゲート前 | V38: 当社 事業部長・品質保証部門・PM
B39: チーム内朝会 | G39: タスク進捗・ブロッカーの共有 | Q39: 毎日（15分） | V39: 当社メンバー全員
B41: 体制設計のポイント
B42: ・要所（PM・業務リード・アーキテクト・開発リーダー）の4名を社員とし、意思決定・顧客接点・品質の要を自社で押さえる。パートナーは実装・基盤構築・テスト・移行に配置（人数・人月・各月のいずれでも60%以内）。
B43: ・B社との窓口は情シスPJ推進担当に一本化。要件決定はKP（部門長任命・要件定義権限あり）、予算・スコープの最終決裁はPOと、決裁ルートを明確化して手戻りを防ぐ。
B44: ・既存ベンダーはリプレースされる側で協力が得にくいため、B社経由で協力範囲を契約化し、三者連絡会で照会・依頼事項を期限付きで管理する。旧環境運用〜停止までの役割を持たせ、最後まで関与を維持する。
B45: ・運用の受け手は情シス。M10から運用設計・引継ぎを並行し、M12のハイパーケア中に受入を完了させる。

Sheet 要員計画
A1: ③ フェーズ別要員計画（チーム別山積み表）
A2: 単位：人（各月の要員数。0.5＝半月稼働） ※パートナーは（P）
A4: ■ チーム別山積み表
A5: チーム | D5: M1 | E5: M2 | F5: M3 | G5: M4 | H5: M5 | I5: M6 | J5: M7 | K5: M8 | L5: M9 | M5: M10 | N5: M11 | O5: M12 | P5: 合計人月 | Q5: 金額(万円)
A6: 主なフェーズ | D6: 立上げ 要件定義 | E6: 要件定義 基盤設計 | F6: 要件定義 基盤設計 | G6: 設計 PoC | H6: 設計 環境構築 | I6: 開発 移行設計 | J6: 開発 テスト計画 | K6: 開発 結合テスト | L6: ST リハ① | M6: UAT リハ② | N6: 本番移行 リリース | O6: 定着 クローズ
A7: PMチーム | D7: =SUMIF($B$20:$B$29,$A7,D$20:D$29) -> 1 | E7: =SUMIF($B$20:$B$29,$A7,E$20:E$29) -> 1 | F7: =SUMIF($B$20:$B$29,$A7,F$20:F$29) -> 1 | G7: =SUMIF($B$20:$B$29,$A7,G$20:G$29) -> 1 | H7: =SUMIF($B$20:$B$29,$A7,H$20:H$29) -> 1 | I7: =SUMIF($B$20:$B$29,$A7,I$20:I$29) -> 1 | J7: =SUMIF($B$20:$B$29,$A7,J$20:J$29) -> 1 | K7: =SUMIF($B$20:$B$29,$A7,K$20:K$29) -> 1 | ... O7: =SUMIF($B$20:$B$29,$A7,O$20:O$29) -> 1 | P7: =SUM(D7:O7) -> 12 | Q7: =SUMIF($B$20:$B$29,$A7,$Q$20:$Q$29) -> 1800
A8: 業務チーム | D8: =SUMIF($B$20:$B$29,$A8,D$20:D$29) -> 1 | E8: =SUMIF($B$20:$B$29,$A8,E$20:E$29) -> 2 | F8: =SUMIF($B$20:$B$29,$A8,F$20:F$29) -> 2 | G8: =SUMIF($B$20:$B$29,$A8,G$20:G$29) -> 1 | H8: =SUMIF($B$20:$B$29,$A8,H$20:H$29) -> 1 | I8: =SUMIF($B$20:$B$29,$A8,I$20:I$29) -> 0.5 | J8: =SUMIF($B$20:$B$29,$A8,J$20:J$29) -> 0.5 | K8: =SUMIF($B$20:$B$29,$A8,K$20:K$29) -> 0.5 | ... O8: =SUMIF($B$20:$B$29,$A8,O$20:O$29) -> 1 | P8: =SUM(D8:O8) -> 12 | Q8: =SUMIF($B$20:$B$29,$A8,$Q$20:$Q$29) -> 1700
A9: 基盤チーム | D9: =SUMIF($B$20:$B$29,$A9,D$20:D$29) -> 1 | E9: =SUMIF($B$20:$B$29,$A9,E$20:E$29) -> 2 | F9: =SUMIF($B$20:$B$29,$A9,F$20:F$29) -> 2 | G9: =SUMIF($B$20:$B$29,$A9,G$20:G$29) -> 2 | H9: =SUMIF($B$20:$B$29,$A9,H$20:H$29) -> 2 | I9: =SUMIF($B$20:$B$29,$A9,I$20:I$29) -> 1 | J9: =SUMIF($B$20:$B$29,$A9,J$20:J$29) -> 1 | K9: =SUMIF($B$20:$B$29,$A9,K$20:K$29) -> 1 | ... O9: =SUMIF($B$20:$B$29,$A9,O$20:O$29) -> 0.5 | P9: =SUM(D9:O9) -> 16.5 | Q9: =SUMIF($B$20:$B$29,$A9,$Q$20:$Q$29) -> 2075
A10: 開発チーム | D10: =SUMIF($B$20:$B$29,$A10,D$20:D$29) -> 0 | E10: =SUMIF($B$20:$B$29,$A10,E$20:E$29) -> 0 | F10: =SUMIF($B$20:$B$29,$A10,F$20:F$29) -> 0 | G10: =SUMIF($B$20:$B$29,$A10,G$20:G$29) -> 3 | H10: =SUMIF($B$20:$B$29,$A10,H$20:H$29) -> 3 | I10: =SUMIF($B$20:$B$29,$A10,I$20:I$29) -> 3 | J10: =SUMIF($B$20:$B$29,$A10,J$20:J$29) -> 3 | K10: =SUMIF($B$20:$B$29,$A10,K$20:K$29) -> 3 | ... O10: =SUMIF($B$20:$B$29,$A10,O$20:O$29) -> 0 | P10: =SUM(D10:O10) -> 19 | Q10: =SUMIF($B$20:$B$29,$A10,$Q$20:$Q$29) -> 2250
A11: テストチーム | D11: =SUMIF($B$20:$B$29,$A11,D$20:D$29) -> 0 | E11: =SUMIF($B$20:$B$29,$A11,E$20:E$29) -> 0 | F11: =SUMIF($B$20:$B$29,$A11,F$20:F$29) -> 0 | G11: =SUMIF($B$20:$B$29,$A11,G$20:G$29) -> 0 | H11: =SUMIF($B$20:$B$29,$A11,H$20:H$29) -> 0 | I11: =SUMIF($B$20:$B$29,$A11,I$20:I$29) -> 0 | J11: =SUMIF($B$20:$B$29,$A11,J$20:J$29) -> 1 | K11: =SUMIF($B$20:$B$29,$A11,K$20:K$29) -> 1 | ... O11: =SUMIF($B$20:$B$29,$A11,O$20:O$29) -> 0 | P11: =SUM(D11:O11) -> 4 | Q11: =SUMIF($B$20:$B$29,$A11,$Q$20:$Q$29) -> 400
A12: 移行チーム | D12: =SUMIF($B$20:$B$29,$A12,D$20:D$29) -> 0 | E12: =SUMIF($B$20:$B$29,$A12,E$20:E$29) -> 0 | F12: =SUMIF($B$20:$B$29,$A12,F$20:F$29) -> 0 | G12: =SUMIF($B$20:$B$29,$A12,G$20:G$29) -> 0 | H12: =SUMIF($B$20:$B$29,$A12,H$20:H$29) -> 0 | I12: =SUMIF($B$20:$B$29,$A12,I$20:I$29) -> 1 | J12: =SUMIF($B$20:$B$29,$A12,J$20:J$29) -> 1 | K12: =SUMIF($B$20:$B$29,$A12,K$20:K$29) -> 1 | ... O12: =SUMIF($B$20:$B$29,$A12,O$20:O$29) -> 0 | P12: =SUM(D12:O12) -> 6 | Q12: =SUMIF($B$20:$B$29,$A12,$Q$20:$Q$29) -> 600
A13: 合計（人） | D13: =SUM(D7:D12) -> 3 | E13: =SUM(E7:E12) -> 5 | F13: =SUM(F7:F12) -> 5 | G13: =SUM(G7:G12) -> 7 | H13: =SUM(H7:H12) -> 7 | I13: =SUM(I7:I12) -> 6.5 | J13: =SUM(J7:J12) -> 7.5 | K13: =SUM(K7:K12) -> 7.5 | ... Q13: =SUM(Q7:Q12) -> 8825
A14: うち社員 | D14: =SUMIF($C$20:$C$29,"社員",D$20:D$29) -> 3 | E14: =SUMIF($C$20:$C$29,"社員",E$20:E$29) -> 3 | F14: =SUMIF($C$20:$C$29,"社員",F$20:F$29) -> 3 | G14: =SUMIF($C$20:$C$29,"社員",G$20:G$29) -> 4 | H14: =SUMIF($C$20:$C$29,"社員",H$20:H$29) -> 4 | I14: =SUMIF($C$20:$C$29,"社員",I$20:I$29) -> 3 | J14: =SUMIF($C$20:$C$29,"社員",J$20:J$29) -> 3 | K14: =SUMIF($C$20:$C$29,"社員",K$20:K$29) -> 3 | ... Q14: =SUMIF($C$20:$C$29,"社員",Q$20:Q$29) -> 5625
A15: うちパートナー（P） | D15: =SUMIF($C$20:$C$29,"パートナー",D$20:D$29) -> 0 | E15: =SUMIF($C$20:$C$29,"パートナー",E$20:E$29) -> 2 | F15: =SUMIF($C$20:$C$29,"パートナー",F$20:F$29) -> 2 | G15: =SUMIF($C$20:$C$29,"パートナー",G$20:G$29) -> 3 | H15: =SUMIF($C$20:$C$29,"パートナー",H$20:H$29) -> 3 | I15: =SUMIF($C$20:$C$29,"パートナー",I$20:I$29) -> 3.5 | J15: =SUMIF($C$20:$C$29,"パートナー",J$20:J$29) -> 4.5 | K15: =SUMIF($C$20:$C$29,"パートナー",K$20:K$29) -> 4.5 | ... Q15: =SUMIF($C$20:$C$29,"パートナー",Q$20:Q$29) -> 3200
A16: パートナー比率（月別） | D16: =IF(D13=0,0,D15/D13) -> 0 | E16: =IF(E13=0,0,E15/E13) -> 0.4 | F16: =IF(F13=0,0,F15/F13) -> 0.4 | G16: =IF(G13=0,0,G15/G13) -> 0.42857143 | H16: =IF(H13=0,0,H15/H13) -> 0.42857143 | I16: =IF(I13=0,0,I15/I13) -> 0.53846154 | J16: =IF(J13=0,0,J15/J13) -> 0.6 | K16: =IF(K13=0,0,K15/K13) -> 0.6 | ... P16: =IF(P13=0,0,P15/P13) -> 0.46043165
A18: ■ 要員明細（役割別）
A19: 役割 | B19: チーム | C19: 区分 | D19: M1 | E19: M2 | F19: M3 | G19: M4 | H19: M5 | I19: M6 | J19: M7 | K19: M8 | L19: M9 | M19: M10 | N19: M11 | O19: M12 | P19: 合計人月 | Q19: 金額(万円)
A20: PM | B20: PMチーム | C20: 社員 | D20: 1 | E20: 1 | F20: 1 | G20: 1 | H20: 1 | I20: 1 | J20: 1 | K20: 1 | L20: 1 | M20: 1 | N20: 1 | O20: 1 | P20: =SUM(D20:O20) -> 12 | Q20: =P20*IF(C20="社員",前提・予算!$B$5,前提・予算!$B$6) -> 1800
A21: 業務リード | B21: 業務チーム | C21: 社員 | D21: 1 | E21: 1 | F21: 1 | G21: 1 | H21: 1 | I21: 0.5 | J21: 0.5 | K21: 0.5 | L21: 1 | M21: 1 | N21: 0.5 | O21: 1 | P21: =SUM(D21:O21) -> 10 | Q21: =P21*IF(C21="社員",前提・予算!$B$5,前提・予算!$B$6) -> 1500
A22: 業務SE（P） | B22: 業務チーム | C22: パートナー | E22: 1 | F22: 1 | P22: =SUM(D22:O22) -> 2 | Q22: =P22*IF(C22="社員",前提・予算!$B$5,前提・予算!$B$6) -> 200
A23: アーキテクト（基盤リード） | B23: 基盤チーム | C23: 社員 | D23: 1 | E23: 1 | F23: 1 | G23: 1 | H23: 1 | I23: 0.5 | J23: 0.5 | K23: 0.5 | L23: 0.5 | M23: 0.5 | N23: 0.5 | O23: 0.5 | P23: =SUM(D23:O23) -> 8.5 | Q23: =P23*IF(C23="社員",前提・予算!$B$5,前提・予算!$B$6) -> 1275
A24: AWSエンジニア（P） | B24: 基盤チーム | C24: パートナー | E24: 1 | F24: 1 | G24: 1 | H24: 1 | I24: 0.5 | J24: 0.5 | K24: 0.5 | L24: 0.5 | M24: 1 | N24: 1 | P24: =SUM(D24:O24) -> 8 | Q24: =P24*IF(C24="社員",前提・予算!$B$5,前提・予算!$B$6) -> 800
A25: 開発リーダー | B25: 開発チーム | C25: 社員 | G25: 1 | H25: 1 | I25: 1 | J25: 1 | K25: 1 | L25: 1 | M25: 1 | P25: =SUM(D25:O25) -> 7 | Q25: =P25*IF(C25="社員",前提・予算!$B$5,前提・予算!$B$6) -> 1050
A26: 開発メンバー（販売管理）（P） | B26: 開発チーム | C26: パートナー | G26: 1 | H26: 1 | I26: 1 | J26: 1 | K26: 1 | L26: 1 | P26: =SUM(D26:O26) -> 6 | Q26: =P26*IF(C26="社員",前提・予算!$B$5,前提・予算!$B$6) -> 600
A27: 開発メンバー（在庫管理）（P） | B27: 開発チーム | C27: パートナー | G27: 1 | H27: 1 | I27: 1 | J27: 1 | K27: 1 | L27: 1 | P27: =SUM(D27:O27) -> 6 | Q27: =P27*IF(C27="社員",前提・予算!$B$5,前提・予算!$B$6) -> 600
A28: テスト担当（P） | B28: テストチーム | C28: パートナー | J28: 1 | K28: 1 | L28: 1 | M28: 1 | P28: =SUM(D28:O28) -> 4 | Q28: =P28*IF(C28="社員",前提・予算!$B$5,前提・予算!$B$6) -> 400
A29: 移行担当（P） | B29: 移行チーム | C29: パートナー | I29: 1 | J29: 1 | K29: 1 | L29: 1 | M29: 1 | N29: 1 | P29: =SUM(D29:O29) -> 6 | Q29: =P29*IF(C29="社員",前提・予算!$B$5,前提・予算!$B$6) -> 600
A31: ■ 集計・パートナー比率チェック
A32: 項目 | B32: 社員 | C32: パートナー | D32: 合計 | E32: 比率/判定
A33: 人数（名） | B33: =COUNTIF(C20:C29,"社員") -> 4 | C33: =COUNTIF(C20:C29,"パートナー") -> 6 | D33: =B33+C33 -> 10 | E33: =C33/D33 -> 0.6
A34: 人月 | B34: =SUMIF(C20:C29,"社員",P20:P29) -> 37.5 | C34: =SUMIF(C20:C29,"パートナー",P20:P29) -> 32 | D34: =B34+C34 -> 69.5 | E34: =C34/D34 -> 0.46043165
A35: 金額（万円） | B35: =SUMIF(C20:C29,"社員",Q20:Q29) -> 5625 | C35: =SUMIF(C20:C29,"パートナー",Q20:Q29) -> 3200 | D35: =B35+C35 -> 8825
A36: 月別パートナー比率の最大 | E36: =MAX(D16:O16) -> 0.6
A37: 上限60%判定（人数・人月・月別） | E37: =IF(AND(E33<=前提・予算!B7,E34<=前提・予算!B7,E36<=前提・予算!B7),"OK","NG") -> OK
A39: ■ WBS工数との整合（チーム別）
A40: チーム | B40: 山積み人月 | C40: WBS工数 | D40: 差異 | E40: 判定
A41: PMチーム | B41: =P7 -> 12 | C41: =SUMIF(WBS!$D$6:$D$92,A41,WBS!$G$6:$G$92) -> 12 | D41: =B41-C41 -> 0 | E41: =IF(ABS(D41)<0.001,"一致","差異あり") -> 一致
A42: 業務チーム | B42: =P8 -> 12 | C42: =SUMIF(WBS!$D$6:$D$92,A42,WBS!$G$6:$G$92) -> 12 | D42: =B42-C42 -> 0 | E42: =IF(ABS(D42)<0.001,"一致","差異あり") -> 一致
A43: 基盤チーム | B43: =P9 -> 16.5 | C43: =SUMIF(WBS!$D$6:$D$92,A43,WBS!$G$6:$G$92) -> 16.5 | D43: =B43-C43 -> 0 | E43: =IF(ABS(D43)<0.001,"一致","差異あり") -> 一致
A44: 開発チーム | B44: =P10 -> 19 | C44: =SUMIF(WBS!$D$6:$D$92,A44,WBS!$G$6:$G$92) -> 19 | D44: =B44-C44 -> 0 | E44: =IF(ABS(D44)<0.001,"一致","差異あり") -> 一致
...

Sheet リスク・ステークホルダー
A1: 主要リスクと対策
A2: No | B2: リスク | C2: 影響 | D2: 発生可能性 | E2: 対策 | F2: 担当
A3: 1 | B3: 要件追加によるスコープ膨張・予算超過 | C3: 大 | D3: 高 | E3: G1でフェーズ1/2のスコープをPO決裁で確定。以降の追加は変更管理票＋ステコミ承認。予備費は承認制で執行。 | F3: PMチーム
A4: 2 | B4: 現行仕様のブラックボックス化 | C4: 大 | D4: 高 | E4: M1〜M2に既存ベンダー協力で資産調査を前倒し。照会は三者連絡会で期限付き管理。 | F4: 基盤チーム
A5: 3 | B5: 既存ベンダーの協力不足（リプレースされる側） | C5: 大 | D5: 中 | E5: 協力範囲をB社経由で契約化（M1）。旧環境運用〜停止まで役割を明確にし関与を維持。 | F5: PMチーム
A6: 4 | B6: KPの要件決定遅延・UAT工数不足 | C6: 大 | D6: 中 | E6: 部門長によるKP任命と要件定義権限の明文化。決定期限を設定し、UAT工数をM7までに部門長と合意。 | F6: 業務チーム
A7: 5 | B7: データ品質不良による移行失敗 | C7: 大 | D7: 中 | E7: M6からクレンジング開始、不備データはKPが業務判断。本番想定リハーサルを2回実施。 | F7: 移行チーム
A8: 6 | B8: 切替時期が月末締め・決算期と重なる | C8: 大 | D8: 中 | E8: 締め・決算を避けた切替日を要件定義で確定。切り戻し手順とGo/No-Go基準を事前合意。 | F8: PMチーム
A9: 7 | B9: 新アーキ/AWSの技術リスク・キーマン依存 | C9: 中 | D9: 中 | E9: M3〜M4のPoCで技術リスクを先に潰す。設計書・レビュー記録で知識を共有。 | F9: 基盤チーム
A10: 8 | B10: 情シスのセキュリティ規程に不適合 | C10: 中 | D10: 低 | E10: M3にセキュリティ設計を情シス承認。技術レビュー会で継続確認。 | F10: 基盤チーム
A11: 9 | B11: 運用引継ぎ不足による稼働後の混乱 | C11: 中 | D11: 中 | E11: M10から運用設計・引継ぎを並行。M12ハイパーケア中に情シスの受入を完了。 | F11: 基盤チーム
A13: ステークホルダー分析
A14: No | B14: 関係者 | C14: 関心事 | D14: 懸念・抵抗 | E14: 関与方法 | F14: 当社窓口
A15: 1 | B15: B社 PO（管掌役員） | C15: 投資対効果・期限・予算 | D15: 予算超過・業務停止 | E15: 月次ステコミで進捗・予算・リスクを報告し、ゲート判定・スコープ決裁を仰ぐ | F15: PMチーム
A16: 2 | B16: B社 情シスPJ推進（2名） | C16: 運用性・セキュリティ・社内調整負荷 | D16: 運用負荷増・規程違反・窓口業務の集中 | E16: 唯一の公式窓口として週次定例で連携。技術レビュー会で設計承認、運用引継ぎを計画的に実施 | F16: PMチーム
A17: 3 | B17: B社 ユーザー部門長 | C17: 業務影響・部門リソース | D17: KP・UAT要員の拘束 | E17: KP任命と要件定義権限の付与を依頼。ステコミ・受入判定で関与 | F17: PMチーム
A18: 4 | B18: B社 KP（営業・経理） | C18: 使いやすさ・締め処理の正確性 | D18: 操作変更への抵抗・通常業務との両立 | E18: 要件・仕様確認会で決定を記録。繁忙期を避けた日程、UAT・社内展開を支援 | F18: 業務チーム
A19: 5 | B19: 既存ベンダー窓口 | C19: 保守契約の継続・終了条件 | D19: 仕事を失う立場で協力に消極的 | E19: B社経由で協力範囲を契約化。三者連絡会で照会・依頼を期限付き管理 | F19: PMチーム
